Workbook
Name avg_equity: Ratios!$C$33
Name avg_total_assets: Ratios!$C$34
Name avg_total_capitalization: Ratios!$C$35
Name cost_capital: Ratios!$C$7
Name currentYear_after_tax_operating_income: Ratios!$C$19
Name currentYear_assets_current: Ratios!$C$23
Name currentYear_assets_total: Ratios!$C$28
Name currentYear_cash_marketable_securities: Ratios!$C$22
Name currentYear_cost_goods_sold_daily: Ratios!$C$25
Name currentYear_daily_sales_average: Ratios!$C$20
Name currentYear_debt_long_term: Ratios!$C$26
Name currentYear_equity: Ratios!$C$21
Name currentYear_liabilities_current: Ratios!$C$24
Name currentYear_liabilities_total: Ratios!$C$30
Name currentYear_total_capitalization: Ratios!$C$29
Name currentYear_working_capital_net: Ratios!$C$27
Name debt_long_term_equity: Ratios!$C$36
Name market_capitalization: Ratios!$C$9
Name share_price: Ratios!$C$5
Name shares_outstanding: Ratios!$C$6
Name startYear_equity: Ratios!$C$12
Name startYear_inventory: Ratios!$C$13
Name startYear_receivables: Ratios!$C$14
Name startYear_total_assets: Ratios!$C$15
Name startYear_total_capitalization: Ratios!$C$16
Name tax_rate: Ratios!$C$8
Name yearCurrent: Ratios!$C$3
Name yearStart: Ratios!$C$4

Sheet Balance Sheet
B1: Balance Sheet — Walmart Inc. (WMT)
B2: ASSETS | C2: FY2025 (Jan 31, 2025) | D2: FY2024 (Jan 31, 2024) | F2: LIABILITIES & EQUITY | G2: FY2025 (Jan 31, 2025) | H2: FY2024 (Jan 31, 2024)
B3: (All figures in $millions) | F3: (All figures in $millions)
B4: Current Assets | F4: Current Liabilities
B5: Cash and marketable securities | C5: 9037 | D5: 9867 | F5: Debt due for repayment | G5: 6466 | H5: 5050
B6: Receivables | C6: 9975 | D6: 8796 | F6: Accounts payable | G6: 58666 | H6: 56812
B7: Inventories | C7: 56435 | D7: 54892 | F7: Other current liabilities | G7: 31452 | H7: 30553
B8: Other current assets | C8: 4011 | D8: 3322 | F8: Total current liabilities | G8: =G5+G6+G7 -> 96584 | H8: =H5+H6+H7 -> 92415
B9: Total current assets | C9: =C5+C6+C7+C8 -> 79458 | D9: =D5+D6+D7+D8 -> 76877
F10: Long-term debt | G10: 33401 | H10: 36132
B11: Fixed Assets | F11: Other long-term liabilities | G11: 33417 | H11: 33503
B12: Property, plant, and equipment | C12: 187483 | D12: 174566
B13: Less accumulated depreciation | C13: 67490 | D13: 63756 | F13: Total Liabilities | G13: =G8+G10+G11 -> 163402 | H13: =H8+H10+H11 -> 162050
B14: Net tangible fixed assets | C14: =C12-C13 -> 119993 | D14: =D12-D13 -> 110810 | H14: 3447
F15: Shareholders' Equity | H15: 36132
B16: Other Assets | C16: 28792 | D16: 28113 | F16: Common stock and paid-in capital | G16: 6305 | H16: 5349
B17: Intangible assets (goodwill) | C17: 32580 | D17: 36599 | F17: Retained earnings | G17: 91116 | H17: 85000
B18: Other assets | C18: =G20-C9-C14-C17 -> 28792 | D18: =H20-D9-D14-D17 -> 28113 | F18: Total shareholders' equity | G18: =G16+G17 -> 97421 | H18: =H16+H17 -> 90349
B20: Total Assets | C20: =C9+C14+C16+C17 -> 260823 | D20: =D9+D14+D16+D17 -> 252399 | F20: Total Liabilities + Equity | G20: =G13+G18 -> 260823 | H20: =H13+H18 -> 252399
B21: Balance Check (TA − TL&E) | C21: =C20-G20 -> 0
B22: Source: Walmart 10-K FY2025, SEC EDGAR

Sheet Income Statement
B1: Income Statement — Walmart Inc. (WMT)
B2: Line Item | C2: FY2025 (Jan 31, 2025) | D2: % of Sales
B3: (All figures in $millions)
B4: Net sales | C4: 674538 | D4: =IF(C$4=0,0,C4/C$4) -> 1
B5: less Cost of goods sold | C5: 511753 | D5: =IF(C$4=0,0,C5/C$4) -> 0.75867186
B6: less Selling, general & administrative (SG&A) | C6: 139884 | D6: =IF(C$4=0,0,C6/C$4) -> 0.20737749
B7: less Depreciation | C7: 12973 | D7: 0.018409284
B8: Earnings before interest & taxes (EBIT) | C8: 29348 | D8: =IF(C$4=0,0,C8/C$4) -> 0.043508298
D9: =IF(C$4=0,0,C9/C$4) -> 0
B10: plus Membership & other income | C10: 6447 | D10: =IF(C$4=0,0,C10/C$4) -> 0.0095576528
B11: less Interest, net | C11: 2245 | D11: 0.0029075015
B12: Pre-tax income | C12: =C8-C11 -> 27103 | D12: =IF(C$4=0,0,C12/C$4) -> 0.040180094
D13: =IF(C$4=0,0,C13/C$4) -> 0
B14: less Taxes | C14: 6152 | D14: 0.0078051959
B15: Net income | C15: =C12-C14 -> 20951 | D15: =IF(C$4=0,0,C15/C$4) -> 0.031059777
D16: =IF(C$4=0,0,C16/C$4) -> 0
B17: Allocation of Net Income | C17: =C15 -> 20951 | D17: =IF(C$4=0,0,C17/C$4) -> 0.031059777
B18: Dividends | C18: 6688 | D18: =IF(C$4=0,0,C18/C$4) -> 0.0099149344
B19: Addition to retained earnings | C19: =C17-C18 -> 14263 | D19: =IF(C$4=0,0,C19/C$4) -> 0.021144843
B21: Source: Walmart 10-K FY2025, SEC EDGAR

Sheet Cash Flow Statement
B1: Cash Flow Statement — Walmart Inc. (WMT)
B2: Line Item | C2: FY2025 (Jan 31, 2025) | D2: Source / Notes
B3: (All figures in $millions)
B4: Operations:
B5: Net income | C5: ='Income Statement'!C15 -> 20951 | D5: [Income Statement]
B6: plus Depreciation | C6: 12973 | D6: [Income Statement]
B7: plus Changes in working capital items
B8: Decrease (increase) in accounts receivable | C8: -1179 | D8: [Balance Sheet]
B9: Decrease (increase) in inventories | C9: -1543 | D9: [Balance Sheet]
B10: Decrease (increase) in other current assets | C10: -689 | D10: [Balance Sheet]
B11: Increase (decrease) in accounts payable | C11: 1854 | D11: [Balance Sheet]
B12: Increase (decrease) in other current liabilities | C12: 2889 | D12: [Balance Sheet]
B13: Total change in working capital | C13: =SUM(C8:C12) -> 1332
B14: Cash provided by operations | C14: =C5+C6+C13 -> 35256
B16: Investments: | C16: -23783
B17: Capital expenditures | C17: 2616
B18: plus Sales (acquisitions) of long-term assets | C18: -212
B19: plus Other investing activities | C19: -4012
B20: Cash provided by (used for) investments | C20: =SUM(C16:C18) -> -21379
C21: 2212
B22: Financing activities: | C22: 2212
B23: Increase (decrease) in short-term debt | C23: -3468
B24: plus Increase (decrease) in long-term debt | C24: -6688
B25: plus Dividends | C25: -4494
B26: plus Issues (repurchases) of stock | C26: -2384
B27: plus Other
B28: Cash provided by (used for) financing | C28: =SUM(C22:C26) -> -14822
B30: Net increase (decrease) in cash | C30: =C14+C20+C28-641 -> -1586
B32: Source: Walmart 10-K FY2025, SEC EDGAR

Sheet Ratios
B1: Ratios — Walmart Inc. (WMT)
B2: Metric | C2: Input | D2: Named Range Formula | E2: Named Range
B3: Current year | C3: 2025 | E3: yearCurrent
B4: Start of year | C4: 2024 | D4: yearCurrent - 1 | E4: yearStart
B5: Share price | C5: 95.08 | E5: share_price
B6: Shares outstanding (M) | C6: 8017 | E6: shares_outstanding
B7: Cost of capital | C7: 0.065 | E7: cost_capital
B8: Tax rate | C8: 0.215 | E8: tax_rate
B9: Market capitalization | C9: =C5*C6 -> 762256.36 | D9: share_price × shares_outstanding | E9: market_capitalization
B11: ─── Start of Year (Prior Year Balance Sheet) ───
B12: Equity (start of year) | C12: ='Balance Sheet'!H18 -> 90349 | D12: BAL_equity_shareholders_2024 | E12: startYear_equity
B13: Inventories (start of year) | C13: ='Balance Sheet'!D7 -> 54892 | D13: BAL_inventories_2024 | E13: startYear_inventory
B14: Receivables (start of year) | C14: ='Balance Sheet'!D6 -> 8796 | D14: BAL_receivables_2024 | E14: startYear_receivables
B15: Total assets (start of year) | C15: ='Balance Sheet'!D20 -> 252399 | D15: BAL_assets_total_2024 | E15: startYear_total_assets
B16: Total capitalization (start of year) | C16: ='Balance Sheet'!H10+'Balance Sheet'!H18 -> 126481 | D16: BAL_debt_long_term_2024 + BAL_equity_shareholders_2024 | E16: startYear_total_capitalization
B18: ─── Current Year (Derived) ───
B19: After-tax operating income | C19: ='Income Statement'!C15+(1-C8)*'Income Statement'!C11 -> 22713.325 | D19: INC_net + (1−tax_rate) × INC_interest_net | E19: currentYear_after_tax_operating_income
B20: Average daily sales | C20: ='Income Statement'!C4/365 -> 1848.0493 | D20: INC_sales / 365 | E20: currentYear_daily_sales_average
B21: Book value of equity | C21: ='Balance Sheet'!G18 -> 97421 | D21: BAL_equity_shareholders_2025 | E21: currentYear_equity
B22: Cash + Mktable securities | C22: ='Balance Sheet'!C5 -> 9037 | D22: BAL_cash_marketable_securities_2025 | E22: currentYear_cash_marketable_securities
B23: Current assets | C23: ='Balance Sheet'!C9 -> 79458 | D23: BAL_assets_current_2025 | E23: currentYear_assets_current
B24: Current liabilities | C24: ='Balance Sheet'!G8 -> 96584 | D24: BAL_liabilities_current_2025 | E24: currentYear_liabilities_current
B25: Daily COGS | C25: ='Income Statement'!C5/365 -> 1402.063 | D25: INC_cost_goods_sold / 365 | E25: currentYear_cost_goods_sold_daily
B26: Long-term debt | C26: ='Balance Sheet'!G10 -> 33401 | D26: BAL_debt_long_term_2025 | E26: currentYear_debt_long_term
B27: Net working capital | C27: ='Balance Sheet'!C9-'Balance Sheet'!G8 -> -17126 | D27: BAL_assets_current_2025 − BAL_liabilities_current_2025 | E27: currentYear_working_capital_net
B28: Total assets | C28: ='Balance Sheet'!C20 -> 260823 | D28: BAL_assets_total_2025 | E28: currentYear_assets_total
B29: Total capitalization | C29: ='Balance Sheet'!G10+'Balance Sheet'!G18 -> 130822 | D29: BAL_debt_long_term_2025 + BAL_equity_shareholders_2025 | E29: currentYear_total_capitalization
B30: Total liabilities | C30: ='Balance Sheet'!G13 -> 163402 | D30: BAL_liabilities_total_2025 | E30: currentYear_liabilities_total
B32: ─── Mixed Year (Averages) ───
B33: Average equity | C33: =AVERAGE(C12,C21) -> 93885 | D33: AVERAGE(startYear_equity, currentYear_equity) | E33: avg_equity
B34: Average total assets | C34: =AVERAGE(C15,C28) -> 256611 | D34: AVERAGE(startYear_total_assets, currentYear_assets_total) | E34: avg_total_assets
B35: Average total capitalization | C35: =AVERAGE(C16,C29) -> 128651.5 | D35: AVERAGE(startYear_total_capitalization, currentYear_total_capitalization) | E35: avg_total_capitalization
B36: Long-term debt + Equity | C36: =C26+C21 -> 130822 | D36: currentYear_debt_long_term + currentYear_equity | E36: debt_long_term_equity
B39: Ratio | C39: Output ← Students Complete | D39: Named Range Formula (reference) | E39: Named Range
B40: Performance
B41: Market value added (MVA) | D41: market_capitalization − currentYear_equity
B42: Market-to-book ratio | D42: market_capitalization / currentYear_equity
B43: Economic value added (EVA) | D43: currentYear_after_tax_operating_income − (cost_capital × startYear_total_capitalization)
B45: Profitability
B46: Return on assets (ROA) | D46: currentYear_after_tax_operating_income / startYear_total_assets
...

Sheet Notes
B1: Notes & Assumptions — Walmart Inc. (WMT)
B3: Company: | C3: Walmart Inc.
B4: Ticker: | C4: WMT
B5: Industry: | C5: Retail – General Merchandise
B6: Fiscal Year (current): | C6: FY2025 (Jan 31, 2025)
B7: Fiscal Year (prior): | C7: FY2024 (Jan 31, 2024)
B8: Data Source: | C8: Walmart 10-K FY2025, SEC EDGAR
B9: Units: | C9: All figures in millions of US dollars unless otherwise noted.
B10: Tax Rate: | C10: 21.5% — use as analyst assumption (adjust to effective rate if preferred)
B11: Cost of Capital: | C11: 6.5% — estimated WACC; students may refine using CAPM + class methodology
B12: Share Price: | C12: $98.85 — end-of-fiscal-year closing price
B13: Shares Outstanding: | C13: 8,039M shares
B15: BUS-314 Project Use: | C15: This workbook provides real financial statement data for the Accounting & Performance Ratios project.
... B20: AI Usage: | C20: [Document any AI tools used and how they were applied — required per course AI guidelines]
